{
 "cells": [
  {
   "cell_type": "code",
   "execution_count": null,
   "id": "68caf159-8376-455d-a1ff-3df14d59320a",
   "metadata": {},
   "outputs": [],
   "source": [
    "Q1. What is an Exception in python ? Write the difference between exceptions and Syntax errors.\n",
    "\n",
    "ANS--An exception in Python is an error that occurs during the execution of a program.\n",
    "When a situation arises that disrupts the normal flow of the program, Python raises an \n",
    "exception to indicate that an error has occurred.\n",
    "\n",
    "DIFFERENCE BETWEEN EXCEPTIONS AND SYNTAX ERRORS :\n",
    "1.CAUSE \n",
    "Exceptions are raised at runtime when and error occurs during the excution of the program \n",
    "while syntax errors ,on the other hand , occur during the parsing (compilation) phase of the program .\n",
    "2. TIMING :\n",
    "Exceptions occurs at runtime when the specific line of code that triggers the exception is excuted while \n",
    "syntax errors are detected and reported by the python interpreter during the compilation (parsing) phase before the program \n",
    "starts executing .\n"
   ]
  },
  {
   "cell_type": "code",
   "execution_count": null,
   "id": "eeef8b88-7ed9-4cbd-8e20-d446c0b4c31f",
   "metadata": {},
   "outputs": [],
   "source": [
    "Q2. What happens when an exception is not handled ? Explain with an example .\n",
    "\n",
    "ANS--When an exception is not handled, it leads to the termination of the program with an error\n",
    "message (a traceback) that provides information about the unhandled exception and the point in the\n",
    "code where it occurred. The traceback shows the sequence of function calls that led to the exception,\n",
    "helping the developer identify the cause of the error.\n",
    "\n",
    "#EXAMPLE \n",
    "def divide_numbers(a, b):\n",
    "    result = a / b\n",
    "    return result\n",
    "\n",
    "try:\n",
    "    num1 = int(input(\"Enter the first number: \"))\n",
    "    num2 = int(input(\"Enter the second number: \"))\n",
    "    result = divide_numbers(num1, num2)\n",
    "    print(\"Result of division:\", result)\n",
    "except ValueError as ve:\n",
    "    print(\"ValueError: Invalid input. Please enter valid numbers.\")\n"
   ]
  },
  {
   "cell_type": "code",
   "execution_count": null,
   "id": "fe6cb9a7-a277-49a2-a934-5d97142585d1",
   "metadata": {},
   "outputs": [],
   "source": [
    "Q3. Which python statements are used to catch and handled exceptions ? Explain with an example .\n",
    "\n",
    "ANS--try, except, else, and finally statements are used to catch and handle exceptions. The try block\n",
    "is used to enclose the code that might raise an exception, and the except block is used to handle the\n",
    "exception if it occurs. The else block is optional and is executed if no exception occurs, and the finally\n",
    "block is also optional and is executed regardless of whether an exception was raised or not.\n",
    "\n",
    "#EXAMPLE\n",
    "\n",
    "def divide_numbers(a, b):\n",
    "    result = a / b\n",
    "    return result\n",
    "\n",
    "try:\n",
    "    num1 = int(input(\"Enter the first number: \"))\n",
    "    num2 = int(input(\"Enter the second number: \"))\n",
    "    result = divide_numbers(num1, num2)\n",
    "    print(\"Result of division:\", result)\n",
    "except ValueError as ve:\n",
    "    print(\"ValueError: Invalid input. Please enter valid numbers.\")\n",
    "except ZeroDivisionError as ze:\n",
    "    print(\"ZeroDivisionError: Cannot divide by zero.\")\n",
    "else:\n",
    "    print(\"Division successful.\")\n",
    "finally:\n",
    "    print(\"This is the finally block. It will always execute.\")\n"
   ]
  },
  {
   "cell_type": "code",
   "execution_count": null,
   "id": "42e220ed-c3d2-4b8d-8827-44f8610837c3",
   "metadata": {},
   "outputs": [],
   "source": [
    "Q4. Explain with an example :\n",
    "    a. try and else \n",
    "    b. finally \n",
    "    c. raise \n",
    "    \n",
    "ANS--\n",
    "A. try and else :\n",
    "The try and else blocks are used together to handle exceptions and execute code when no\n",
    "exceptions occur. The code inside the try block is executed, and if an exception occurs, it jumps\n",
    "to the corresponding except block (if present) to handle the exception. However, if no exception \n",
    "occurs in the try block, the code inside the else block is executed.\n",
    "\n",
    "#EXAMPLE \n",
    "def divide_numbers(a, b):\n",
    "    result = a / b\n",
    "    return result\n",
    "\n",
    "try:\n",
    "    num1 = int(input(\"Enter the first number: \"))\n",
    "    num2 = int(input(\"Enter the second number: \"))\n",
    "    result = divide_numbers(num1, num2)\n",
    "except ValueError:\n",
    "    print(\"ValueError: Invalid input. Please enter valid numbers.\")\n",
    "else:\n",
    "    print(\"Result of division:\", result)\n",
    "    print(\"Division successful.\")\n",
    "\n",
    "B. finally:\n",
    "The finally block is used to specify code that will be executed regardless of whether an exception\n",
    "was raised or not. It allows you to perform cleanup operations or tasks that must be executed, regardless \n",
    "of the outcome of the try block.\n",
    "\n",
    "#EXAMPLE \n",
    "try:\n",
    "    num = int(input(\"Enter a number: \"))\n",
    "except ValueError:\n",
    "    print(\"ValueError: Invalid input. Please enter a valid number.\")\n",
    "finally:\n",
    "    print(\"This block will always execute, regardless of exceptions.\")\n",
    "\n",
    "C. c. raise:\n",
    "The raise statement is used to manually raise exceptions in Python. You can use it to raise built-in \n",
    "exceptions or create custom exceptions when certain conditions are met.\n",
    "\n",
    "#EXAMPLE \n",
    "def validate_age(age):\n",
    "    if age < 0:\n",
    "        raise ValueError(\"Age cannot be negative.\")\n",
    "    elif age < 18:\n",
    "        raise ValueError(\"You must be 18 years or older.\")\n",
    "\n",
    "try:\n",
    "    user_age = int(input(\"Enter your age: \"))\n",
    "    validate_age(user_age)\n",
    "    print(\"Age is valid:\", user_age)\n",
    "except ValueError as ve:\n",
    "    print(ve)\n"
   ]
  },
  {
   "cell_type": "code",
   "execution_count": null,
   "id": "d684459f-0e6a-462d-ad05-76073ebdcf9c",
   "metadata": {},
   "outputs": [],
   "source": [
    "Q6. What are custom exceptions in python ? Why do we need Custom Exceptions ? Explain with an example .\n",
    "\n",
    "ANS--Custom exceptions in Python are user-defined exceptions that allow developers to create their own \n",
    "specific exception types to handle exceptional conditions in their code. Python allows you to create custom\n",
    "exceptions by creating new classes that inherit from the built-in Exception class or any of its subclasses.\n",
    "\n",
    "NEED OF custom exceptions :\n",
    "1. Better Error Handling \n",
    "2. Modularity and clarity \n",
    "3. Consistent Error Reporting \n",
    "4. "
   ]
  }
 ],
 "metadata": {
  "kernelspec": {
   "display_name": "Python 3 (ipykernel)",
   "language": "python",
   "name": "python3"
  },
  "language_info": {
   "codemirror_mode": {
    "name": "ipython",
    "version": 3
   },
   "file_extension": ".py",
   "mimetype": "text/x-python",
   "name": "python",
   "nbconvert_exporter": "python",
   "pygments_lexer": "ipython3",
   "version": "3.10.8"
  }
 },
 "nbformat": 4,
 "nbformat_minor": 5
}
